<mujoco model="02_Leg_UFDF_260610_8">
  <compiler angle="radian" meshdir="/home/jsh/문서/jsh/simulation/quad/meshes_sim/" />
  <asset>
    <mesh name="base" content_type="model/stl" file="base.STL" />
    <mesh name="HL_hip_link" content_type="model/stl" file="HL_hip_link.STL" />
    <mesh name="HL_thigh_link" content_type="model/stl" file="HL_thigh_link.STL" />
    <mesh name="HL_calf_link" content_type="model/stl" file="HL_calf_link.STL" />
    <mesh name="HL_foot_link" content_type="model/stl" file="HL_foot_link.STL" />
    <mesh name="HL_foot_contact_link" content_type="model/stl" file="HL_foot_contact_link.STL" />
    <mesh name="HR_hip_link" content_type="model/stl" file="HR_hip_link.STL" />
    <mesh name="HR_thigh_link" content_type="model/stl" file="HR_thigh_link.STL" />
    <mesh name="HR_calf_link" content_type="model/stl" file="HR_calf_link.STL" />
    <mesh name="HR_foot_link" content_type="model/stl" file="HR_foot_link.STL" />
    <mesh name="HR_foot_contact_link" content_type="model/stl" file="HR_foot_contact_link.STL" />
    <mesh name="FL_hip_link" content_type="model/stl" file="FL_hip_link.STL" />
    <mesh name="FL_thigh_link" content_type="model/stl" file="FL_thigh_link.STL" />
    <mesh name="FL_calf_link" content_type="model/stl" file="FL_calf_link.STL" />
    <mesh name="FL_foot_link" content_type="model/stl" file="FL_foot_link.STL" />
    <mesh name="FL_foot_contact_link" content_type="model/stl" file="FL_foot_contact_link.STL" />
    <mesh name="FR_hip_link" content_type="model/stl" file="FR_hip_link.STL" />
    <mesh name="FR_thigh_link" content_type="model/stl" file="FR_thigh_link.STL" />
    <mesh name="FR_calf_link" content_type="model/stl" file="FR_calf_link.STL" />
    <mesh name="FR_foot_link" content_type="model/stl" file="FR_foot_link.STL" />
    <mesh name="FR_foot_contact_link" content_type="model/stl" file="FR_foot_contact_link.STL" />
  </asset>
  <worldbody>
    <body name="base" pos="0 0 0.6031">
      <freejoint name="root" />
      <inertial pos="0.075 1.5456e-12 4.1817e-05" quat="0.707106 0.707106 0.000998709 0.000998709" mass="5.617" diaginertia="0.00589992 0.0034812 0.00338838" />
      <geom type="mesh" contype="0" conaffinity="0" group="1" density="0" rgba="0.75294 0.75294 0.75294 1" mesh="base" />
      <geom type="mesh" rgba="0.75294 0.75294 0.75294 1" mesh="base" />
      <body name="HL_hip_link" pos="-0.225 0.0225 0">
        <inertial pos="0.03558 0.0378375 -4.9865e-06" mass="1.3265" fullinertia="0.00055394 0.00080297 0.000457195 8.00135e-06 0 0" />
        <joint name="HL_hip_joint" pos="0 0 0" axis="1 0 0" range="-0.6109 0.6109" actuatorfrcrange="-84 84" />
        <geom type="mesh" contype="0" conaffinity="0" group="1" density="0" rgba="0.75294 0.75294 0.75294 1" mesh="HL_hip_link" />
        <geom type="mesh" rgba="0.75294 0.75294 0.75294 1" mesh="HL_hip_link" />
        <body name="HL_thigh_link" pos="0 0.115 0">
          <inertial pos="0.032414 0.000792805 -0.089056" mass="3.021" fullinertia="0.00400885 0.005605 0.00170025 2.18635e-07 0.00096858 -6.0068e-07" />
          <joint name="HL_thigh_joint" pos="0 0 0" axis="0 1 0" range="-1.396 2.094" actuatorfrcrange="-84 84" />
          <geom type="mesh" contype="0" conaffinity="0" group="1" density="0" rgba="0.75294 0.75294 0.75294 1" mesh="HL_thigh_link" />
          <geom type="mesh" rgba="0.75294 0.75294 0.75294 1" mesh="HL_thigh_link" />
          <body name="HL_calf_link" pos="0.078665 0 -0.21613">
            <inertial pos="-0.04561 0.00012675 -0.084011" quat="0.683134 0.18256 0.18256 0.683134" mass="0.592" diaginertia="0.0024327 0.0023203 0.000138265" />
            <joint name="HL_calf_joint" pos="0 0 0" axis="0 1 0" range="-0.524 1.484" actuatorfrcrange="-126 126" />
            <geom type="mesh" contype="0" conaffinity="0" group="1" density="0" rgba="0.75294 0.75294 0.75294 1" mesh="HL_calf_link" />
            <geom type="mesh" rgba="0.75294 0.75294 0.75294 1" mesh="HL_calf_link" />
            <body name="HL_foot_link" pos="-0.1225 0 -0.21218">
              <inertial pos="0.021095 -1.3548e-12 -0.057957" quat="0.696362 -0.12279 -0.122789 0.696365" mass="0.20444" diaginertia="0.00030517 0.000278691 3.05195e-05" />
              <joint name="HL_foot_joint" pos="0 0 0" axis="0 1 0" range="-1.571 0.524" actuatorfrcrange="-168 168" />
              <geom type="mesh" contype="0" conaffinity="0" group="1" density="0" rgba="0.75294 0.75294 0.75294 1" mesh="HL_foot_link" />
              <geom type="mesh" rgba="0.75294 0.75294 0.75294 1" mesh="HL_foot_link" />
              <body name="HL_foot_contact_link" pos="0.0376222 0 -0.103366">
                <inertial pos="0.016812 0 -0.04619" quat="0.579233 0.405573 0.405573 0.579233" mass="0.033311" diaginertia="1.0583e-05 7.75194e-06 6.94896e-06" />
                <geom type="mesh" contype="0" conaffinity="0" group="1" density="0" rgba="1 1 1 1" mesh="HL_foot_contact_link" />
                <geom name="HL_sphere" type="sphere" size="0.018" pos="0 -0.0035 -0.052" rgba="0.9 0.3 0.3 1" friction="0.9 0.02 0.001" condim="3" />
              </body>
            </body>
          </body>
        </body>
      </body>
      <body name="HR_hip_link" pos="-0.225 -0.0225 0">
        <inertial pos="0.03558 -0.0378375 -4.9865e-06" mass="1.3265" fullinertia="0.00055394 0.00080297 0.000457195 -8.00135e-06 0 -0" />
        <joint name="HR_hip_joint" pos="0 0 0" axis="1 0 0" range="-0.6109 0.6109" actuatorfrcrange="-84 84" />
        <geom type="mesh" contype="0" conaffinity="0" group="1" density="0" rgba="0.75294 0.75294 0.75294 1" mesh="HR_hip_link" />
        <geom type="mesh" rgba="0.75294 0.75294 0.75294 1" mesh="HR_hip_link" />
        <body name="HR_thigh_link" pos="0 -0.115 0">
          <inertial pos="0.032414 -0.000792805 -0.089056" mass="3.021" fullinertia="0.00400885 0.005605 0.00170025 -2.18635e-07 0.00096858 6.0068e-07" />
          <joint name="HR_thigh_joint" pos="0 0 0" axis="0 1 0" range="-1.396 2.094" actuatorfrcrange="-84 84" />
          <geom type="mesh" contype="0" conaffinity="0" group="1" density="0" rgba="0.75294 0.75294 0.75294 1" mesh="HR_thigh_link" />
          <geom type="mesh" rgba="0.75294 0.75294 0.75294 1" mesh="HR_thigh_link" />
          <body name="HR_calf_link" pos="0.078665 0 -0.21613">
            <inertial pos="-0.04561 -0.00012405 -0.084011" quat="0.683134 0.18256 0.18256 0.683134" mass="0.592" diaginertia="0.0024327 0.0023203 0.000138265" />
            <joint name="HR_calf_joint" pos="0 0 0" axis="0 1 0" range="-0.524 1.484" actuatorfrcrange="-126 126" />
            <geom type="mesh" contype="0" conaffinity="0" group="1" density="0" rgba="0.75294 0.75294 0.75294 1" mesh="HR_calf_link" />
            <geom type="mesh" rgba="0.75294 0.75294 0.75294 1" mesh="HR_calf_link" />
            <body name="HR_foot_link" pos="-0.1225 0 -0.21218">
              <inertial pos="0.021095 -1.3544e-12 -0.057957" quat="0.696362 -0.12279 -0.122789 0.696365" mass="0.20444" diaginertia="0.00030517 0.000278691 3.05195e-05" />
              <joint name="HR_foot_joint" pos="0 0 0" axis="0 1 0" range="-1.571 0.524" actuatorfrcrange="-168 168" />
              <geom type="mesh" contype="0" conaffinity="0" group="1" density="0" rgba="0.75294 0.75294 0.75294 1" mesh="HR_foot_link" />
              <geom type="mesh" rgba="0.75294 0.75294 0.75294 1" mesh="HR_foot_link" />
              <body name="HR_foot_contact_link" pos="0.0376222 0 -0.103366">
                <inertial pos="0.016812 0 -0.04619" quat="0.579233 0.405573 0.405573 0.579233" mass="0.033311" diaginertia="1.0583e-05 7.75194e-06 6.94896e-06" />
                <geom type="mesh" contype="0" conaffinity="0" group="1" density="0" rgba="1 1 1 1" mesh="HR_foot_contact_link" />
                <geom name="HR_sphere" type="sphere" size="0.018" pos="0 -0.0035 -0.052" rgba="0.9 0.3 0.3 1" friction="0.9 0.02 0.001" condim="3" />
              </body>
            </body>
          </body>
        </body>
      </body>
      <body name="FL_hip_link" pos="0.375 0.0225 0">
        <inertial pos="-0.03558 0.0378375 -4.9865e-06" mass="1.3265" fullinertia="0.00055394 0.00080297 0.000457195 -8.00135e-06 0 0" />
        <joint name="FL_hip_joint" pos="0 0 0" axis="1 0 0" range="-0.6109 0.6109" actuatorfrcrange="-84 84" />
        <geom type="mesh" contype="0" conaffinity="0" group="1" density="0" rgba="0.75294 0.75294 0.75294 1" mesh="FL_hip_link" />
        <geom type="mesh" rgba="0.75294 0.75294 0.75294 1" mesh="FL_hip_link" />
        <body name="FL_thigh_link" pos="0 0.115 0">
          <inertial pos="-0.0245285 0.0007928 -0.091542" mass="3.021" fullinertia="0.0041595 0.005605 0.0015496 -1.654545e-07 -0.00075342 -6.1745e-07" />
          <joint name="FL_thigh_joint" pos="0 0 0" axis="0 1 0" range="-2.0071 1.484" actuatorfrcrange="-84 84" />
          <geom type="mesh" contype="0" conaffinity="0" group="1" density="0" rgba="0.75294 0.75294 0.75294 1" mesh="FL_thigh_link" />
          <geom type="mesh" rgba="0.75294 0.75294 0.75294 1" mesh="FL_thigh_link" />
          <body name="FL_calf_link" pos="-0.059528 0 -0.22216">
            <inertial pos="0.014126 0.00012405 -0.094544" quat="0.704457 -0.0611613 -0.0611613 0.704457" mass="0.592" diaginertia="0.0024327 0.00232031 0.00013827" />
            <joint name="FL_calf_joint" pos="0 0 0" axis="0 1 0" range="-1.9199 0.087" actuatorfrcrange="-126 126" />
            <geom type="mesh" contype="0" conaffinity="0" group="1" density="0" rgba="0.75294 0.75294 0.75294 1" mesh="FL_calf_link" />
            <geom type="mesh" rgba="0.75294 0.75294 0.75294 1" mesh="FL_calf_link" />
            <body name="FL_foot_link" pos="0.042544 0 -0.24128">
              <inertial pos="0.010724 -1.3835e-12 -0.040023" quat="0.701046 -0.0922999 -0.0922971 0.701068" mass="0.15434" diaginertia="0.00013375 0.000113398 2.37161e-05" />
              <joint name="FL_foot_joint" pos="0 0 0" axis="0 1 0" range="-1.309 0.785" actuatorfrcrange="-168 168" />
              <geom type="mesh" contype="0" conaffinity="0" group="1" density="0" rgba="0.75294 0.75294 0.75294 1" mesh="FL_foot_link" />
              <geom type="mesh" rgba="0.75294 0.75294 0.75294 1" mesh="FL_foot_link" />
              <body name="FL_foot_contact_link" pos="0.0181173 0 -0.0676148">
                <inertial pos="0.012722 0 -0.047479" quat="0.560982 0.430463 0.430463 0.560982" mass="0.033311" diaginertia="1.0583e-05 7.75199e-06 6.94891e-06" />
                <geom type="mesh" contype="0" conaffinity="0" group="1" density="0" rgba="1 1 1 1" mesh="FL_foot_contact_link" />
                <geom name="FL_sphere" type="sphere" size="0.018" pos="0 -0.0035 -0.052" rgba="0.9 0.3 0.3 1" friction="0.9 0.02 0.001" condim="3" />
              </body>
            </body>
          </body>
        </body>
      </body>
      <body name="FR_hip_link" pos="0.375 -0.0225 0">
        <inertial pos="-0.03558 -0.0378375 -4.9865e-06" mass="1.3265" fullinertia="0.00055394 0.00080297 0.000457195 8.00135e-06 0 -0" />
        <joint name="FR_hip_joint" pos="0 0 0" axis="1 0 0" range="-0.6109 0.6109" actuatorfrcrange="-84 84" />
        <geom type="mesh" contype="0" conaffinity="0" group="1" density="0" rgba="0.75294 0.75294 0.75294 1" mesh="FR_hip_link" />
        <geom type="mesh" rgba="0.75294 0.75294 0.75294 1" mesh="FR_hip_link" />
        <body name="FR_thigh_link" pos="0 -0.115 0">
          <inertial pos="-0.0245285 -0.0007928 -0.091542" mass="3.021" fullinertia="0.0041595 0.005605 0.0015496 1.654545e-07 -0.00075342 6.1745e-07" />
          <joint name="FR_thigh_joint" pos="0 0 0" axis="0 1 0" range="-2.0071 1.484" actuatorfrcrange="-84 84" />
          <geom type="mesh" contype="0" conaffinity="0" group="1" density="0" rgba="0.75294 0.75294 0.75294 1" mesh="FR_thigh_link" />
          <geom type="mesh" rgba="0.75294 0.75294 0.75294 1" mesh="FR_thigh_link" />
          <body name="FR_calf_link" pos="-0.059528 0 -0.22216">
            <inertial pos="0.014126 -0.00012675 -0.094544" quat="0.704457 -0.0611613 -0.0611613 0.704457" mass="0.592" diaginertia="0.0024327 0.00232031 0.00013827" />
            <joint name="FR_calf_joint" pos="0 0 0" axis="0 1 0" range="-1.9199 0.087" actuatorfrcrange="-126 126" />
            <geom type="mesh" contype="0" conaffinity="0" group="1" density="0" rgba="0.75294 0.75294 0.75294 1" mesh="FR_calf_link" />
            <geom type="mesh" rgba="0.75294 0.75294 0.75294 1" mesh="FR_calf_link" />
            <body name="FR_foot_link" pos="0.042544 0 -0.24128">
              <inertial pos="0.010724 -1.3833e-12 -0.040023" quat="0.701046 -0.0922999 -0.0922971 0.701068" mass="0.15434" diaginertia="0.00013375 0.000113398 2.37161e-05" />
              <joint name="FR_foot_joint" pos="0 0 0" axis="0 1 0" range="-1.309 0.785" actuatorfrcrange="-168 168" />
              <geom type="mesh" contype="0" conaffinity="0" group="1" density="0" rgba="0.75294 0.75294 0.75294 1" mesh="FR_foot_link" />
              <geom type="mesh" rgba="0.75294 0.75294 0.75294 1" mesh="FR_foot_link" />
              <body name="FR_foot_contact_link" pos="0.0181173 0 -0.0676148">
                <inertial pos="0.012722 0 -0.047479" quat="0.560982 0.430463 0.430463 0.560982" mass="0.033311" diaginertia="1.0583e-05 7.75199e-06 6.94891e-06" />
                <geom type="mesh" contype="0" conaffinity="0" group="1" density="0" rgba="1 1 1 1" mesh="FR_foot_contact_link" />
                <geom name="FR_sphere" type="sphere" size="0.018" pos="0 -0.0035 -0.052" rgba="0.9 0.3 0.3 1" friction="0.9 0.02 0.001" condim="3" />
              </body>
            </body>
          </body>
        </body>
      </body>
    </body>
    <geom name="floor" type="plane" size="5 5 0.1" rgba="0.4 0.5 0.4 1" />
    <light pos="0 0 3" dir="0 0 -1" />
  </worldbody>
  <option timestep="0.002" gravity="0 0 -9.81" />
  <default>
    <geom friction="0.9 0.02 0.001" condim="3" />
    <motor ctrllimited="true" ctrlrange="-80 80" />
  </default>
  <actuator>
    <motor joint="HL_hip_joint" name="HL_hip" />
    <motor joint="HL_thigh_joint" name="HL_thigh" />
    <motor joint="HL_calf_joint" name="HL_calf" />
    <motor joint="HL_foot_joint" name="HL_foot" />
    <motor joint="HR_hip_joint" name="HR_hip" />
    <motor joint="HR_thigh_joint" name="HR_thigh" />
    <motor joint="HR_calf_joint" name="HR_calf" />
    <motor joint="HR_foot_joint" name="HR_foot" />
    <motor joint="FL_hip_joint" name="FL_hip" />
    <motor joint="FL_thigh_joint" name="FL_thigh" />
    <motor joint="FL_calf_joint" name="FL_calf" />
    <motor joint="FL_foot_joint" name="FL_foot" />
    <motor joint="FR_hip_joint" name="FR_hip" />
    <motor joint="FR_thigh_joint" name="FR_thigh" />
    <motor joint="FR_calf_joint" name="FR_calf" />
    <motor joint="FR_foot_joint" name="FR_foot" />
  </actuator>
</mujoco>