<?xml version="1.0" encoding="utf-8"?>
<!-- This URDF was automatically created by SolidWorks to URDF Exporter! Originally created by Stephen Brawner (brawner@gmail.com) 
     Commit Version: 1.6.0-4-g7f85cfe  Build Version: 1.6.7995.38578
     For more information, please see http://wiki.ros.org/sw_urdf_exporter -->
<robot
  name="02_Leg_UFDF_260610_8">
  <link
    name="base">
    <inertial>
      <origin
        xyz="0.075 1.5456E-12 4.1817E-05"
        rpy="0 0 0" />
      <mass
        value="5.617" />
      <inertia
        ixx="0.0058999"
        ixy="7.0945E-06"
        ixz="4.1811E-15"
        iyy="0.0033884"
        iyz="-4.4193E-15"
        izz="0.0034812" />
    </inertial>
    <visual>
      <origin
        xyz="0 0 0"
        rpy="0 0 0" />
      <geometry>
        <mesh
          filename="/home/jsh/문서/jsh/simulation/quad/meshes/base.STL" />
      </geometry>
      <material
        name="">
        <color
          rgba="0.75294 0.75294 0.75294 1" />
      </material>
    </visual>
    <collision>
      <origin
        xyz="0 0 0"
        rpy="0 0 0" />
      <geometry>
        <mesh
          filename="/home/jsh/문서/jsh/simulation/quad/meshes/base.STL" />
      </geometry>
    </collision>
  </link>
  <link
    name="HL_hip_link">
    <inertial>
      <origin
        xyz="0.026196 0.039035 -5.8825E-05"
        rpy="0 0 0" />
      <mass
        value="1.268" />
      <inertia
        ixx="0.0005559"
        ixy="1.3767E-05"
        ixz="2.7997E-09"
        iyy="0.00078767"
        iyz="-1.4339E-09"
        izz="0.00044966" />
    </inertial>
    <visual>
      <origin
        xyz="0 0 0"
        rpy="0 0 0" />
      <geometry>
        <mesh
          filename="/home/jsh/문서/jsh/simulation/quad/meshes/HL_hip_link.STL" />
      </geometry>
      <material
        name="">
        <color
          rgba="0.75294 0.75294 0.75294 1" />
      </material>
    </visual>
    <collision>
      <origin
        xyz="0 0 0"
        rpy="0 0 0" />
      <geometry>
        <mesh
          filename="/home/jsh/문서/jsh/simulation/quad/meshes/HL_hip_link.STL" />
      </geometry>
    </collision>
  </link>
  <joint
    name="HL_hip_joint"
    type="revolute">
    <origin
      xyz="-0.225 0.0225 0"
      rpy="0 0 0" />
    <parent
      link="base" />
    <child
      link="HL_hip_link" />
    <axis
      xyz="1 0 0" />
    <limit
      lower="-0.6109"
      upper="0.6109"
      effort="28"
      velocity="29.6" />
  </joint>
  <link
    name="HL_thigh_link">
    <inertial>
      <origin
        xyz="0.033321 0.00079281 -0.088726"
        rpy="0 0 0" />
      <mass
        value="3.021" />
      <inertia
        ixx="0.0040056"
        ixy="2.8469E-07"
        ixz="0.00097243"
        iyy="0.005605"
        iyz="-5.7663E-07"
        izz="0.0017035" />
    </inertial>
    <visual>
      <origin
        xyz="0 0 0"
        rpy="0 0 0" />
      <geometry>
        <mesh
          filename="/home/jsh/문서/jsh/simulation/quad/meshes/HL_thigh_link.STL" />
      </geometry>
      <material
        name="">
        <color
          rgba="0.75294 0.75294 0.75294 1" />
      </material>
    </visual>
    <collision>
      <origin
        xyz="0 0 0"
        rpy="0 0 0" />
      <geometry>
        <mesh
          filename="/home/jsh/문서/jsh/simulation/quad/meshes/HL_thigh_link.STL" />
      </geometry>
    </collision>
  </link>
  <joint
    name="HL_thigh_joint"
    type="revolute">
    <origin
      xyz="0 0.115 0"
      rpy="0 0 0" />
    <parent
      link="HL_hip_link" />
    <child
      link="HL_thigh_link" />
    <axis
      xyz="0 1 0" />
    <limit
      lower="-1.396"
      upper="2.094"
      effort="28"
      velocity="29.6" />
  </joint>
  <link
    name="HL_calf_link">
    <inertial>
      <origin
        xyz="-0.04561 0.00012675 -0.084011"
        rpy="0 0 0" />
      <mass
        value="0.592" />
      <inertia
        ixx="0.0017773"
        ixy="-5.113E-10"
        ixz="-0.0009434"
        iyy="0.0024327"
        iyz="-2.952E-10"
        izz="0.00068127" />
    </inertial>
    <visual>
      <origin
        xyz="0 0 0"
        rpy="0 0 0" />
      <geometry>
        <mesh
          filename="/home/jsh/문서/jsh/simulation/quad/meshes/HL_calf_link.STL" />
      </geometry>
      <material
        name="">
        <color
          rgba="0.75294 0.75294 0.75294 1" />
      </material>
    </visual>
    <collision>
      <origin
        xyz="0 0 0"
        rpy="0 0 0" />
      <geometry>
        <mesh
          filename="/home/jsh/문서/jsh/simulation/quad/meshes/HL_calf_link.STL" />
      </geometry>
    </collision>
  </link>
  <joint
    name="HL_calf_joint"
    type="revolute">
    <origin
      xyz="0.078665 0 -0.21613"
      rpy="0 0 0" />
    <parent
      link="HL_thigh_link" />
    <child
      link="HL_calf_link" />
    <axis
      xyz="0 1 0" />
    <limit
      lower="-0.524"
      upper="1.484"
      effort="42"
      velocity="19.7" />
  </joint>
  <link
    name="HL_foot_link">
    <inertial>
      <origin
        xyz="0.021095 -1.3548E-12 -0.057957"
        rpy="0 0 0" />
      <mass
        value="0.20444" />
      <inertia
        ixx="0.00024966"
        ixy="-1.0271E-10"
        ixz="7.9762E-05"
        iyy="0.00030517"
        iyz="-3.7368E-11"
        izz="5.9551E-05" />
    </inertial>
    <visual>
      <origin
        xyz="0 0 0"
        rpy="0 0 0" />
      <geometry>
        <mesh
          filename="/home/jsh/문서/jsh/simulation/quad/meshes/HL_foot_link.STL" />
      </geometry>
      <material
        name="">
        <color
          rgba="0.75294 0.75294 0.75294 1" />
      </material>
    </visual>
    <collision>
      <origin
        xyz="0 0 0"
        rpy="0 0 0" />
      <geometry>
        <mesh
          filename="/home/jsh/문서/jsh/simulation/quad/meshes/HL_foot_link.STL" />
      </geometry>
    </collision>
  </link>
  <joint
    name="HL_foot_joint"
    type="revolute">
    <origin
      xyz="-0.1225 0 -0.21218"
      rpy="0 0 0" />
    <parent
      link="HL_calf_link" />
    <child
      link="HL_foot_link" />
    <axis
      xyz="0 1 0" />
    <limit
      lower="-1.571"
      upper="0.524"
      effort="56"
      velocity="14.8" />
  </joint>
  <link
    name="HL_foot_contact_link">
    <inertial>
      <origin
        xyz="0.016812 -1.3878E-16 -0.04619"
        rpy="0 0 0" />
      <mass
        value="0.033311" />
      <inertia
        ixx="7.0429E-06"
        ixy="-6.2778E-21"
        ixz="-2.5809E-07"
        iyy="1.0583E-05"
        iyz="-3.3627E-21"
        izz="7.658E-06" />
    </inertial>
    <visual>
      <origin
        xyz="0 0 0"
        rpy="0 0 0" />
      <geometry>
        <mesh
          filename="/home/jsh/문서/jsh/simulation/quad/meshes/HL_foot_contact_link.STL" />
      </geometry>
      <material
        name="">
        <color
          rgba="1 1 1 1" />
      </material>
    </visual>
    <collision>
      <origin
        xyz="0 0 0"
        rpy="0 0 0" />
      <geometry>
        <mesh
          filename="/home/jsh/문서/jsh/simulation/quad/meshes/HL_foot_contact_link.STL" />
      </geometry>
    </collision>
  </link>
  <joint
    name="HL_foot_contact_joint"
    type="fixed">
    <origin
      xyz="0.0376222157658233 0 -0.103366188286448"
      rpy="0 0 0" />
    <parent
      link="HL_foot_link" />
    <child
      link="HL_foot_contact_link" />
    <axis
      xyz="0 0 0" />
  </joint>
  <link
    name="HR_hip_link">
    <inertial>
      <origin
        xyz="0.044964 -0.03664 4.8852E-05"
        rpy="0 0 0" />
      <mass
        value="1.385" />
      <inertia
        ixx="0.00055198"
        ixy="-2.2357E-06"
        ixz="-2.7997E-09"
        iyy="0.00081827"
        iyz="-1.4339E-09"
        izz="0.00046473" />
    </inertial>
    <visual>
      <origin
        xyz="0 0 0"
        rpy="0 0 0" />
      <geometry>
        <mesh
          filename="/home/jsh/문서/jsh/simulation/quad/meshes/HR_hip_link.STL" />
      </geometry>
      <material
        name="">
        <color
          rgba="0.75294 0.75294 0.75294 1" />
      </material>
    </visual>
    <collision>
      <origin
        xyz="0 0 0"
        rpy="0 0 0" />
      <geometry>
        <mesh
          filename="/home/jsh/문서/jsh/simulation/quad/meshes/HR_hip_link.STL" />
      </geometry>
    </collision>
  </link>
  <joint
    name="HR_hip_joint"
    type="revolute">
    <origin
      xyz="-0.225 -0.0225 0"
      rpy="0 0 0" />
    <parent
      link="base" />
    <child
      link="HR_hip_link" />
    <axis
      xyz="1 0 0" />
    <limit
      lower="-0.6109"
      upper="0.6109"
      effort="28"
      velocity="29.6" />
  </joint>
  <link
    name="HR_thigh_link">
    <inertial>
      <origin
        xyz="0.031507 -0.0007928 -0.089386"
        rpy="0 0 0" />
      <mass
        value="3.021" />
      <inertia
        ixx="0.0040121"
        ixy="-1.5258E-07"
        ixz="0.00096473"
        iyy="0.005605"
        iyz="6.2473E-07"
        izz="0.001697" />
    </inertial>
    <visual>
      <origin
        xyz="0 0 0"
        rpy="0 0 0" />
      <geometry>
        <mesh
          filename="/home/jsh/문서/jsh/simulation/quad/meshes/HR_thigh_link.STL" />
      </geometry>
      <material
        name="">
        <color
          rgba="0.75294 0.75294 0.75294 1" />
      </material>
    </visual>
    <collision>
      <origin
        xyz="0 0 0"
        rpy="0 0 0" />
      <geometry>
        <mesh
          filename="/home/jsh/문서/jsh/simulation/quad/meshes/HR_thigh_link.STL" />
      </geometry>
    </collision>
  </link>
  <joint
    name="HR_thigh_joint"
    type="revolute">
    <origin
      xyz="0 -0.115 0"
      rpy="0 0 0" />
    <parent
      link="HR_hip_link" />
    <child
      link="HR_thigh_link" />
    <axis
      xyz="0 1 0" />
    <limit
      lower="-1.396"
      upper="2.094"
      effort="28"
      velocity="29.6" />
  </joint>
  <link
    name="HR_calf_link">
    <inertial>
      <origin
        xyz="-0.04561 -0.00012405 -0.084011"
        rpy="0 0 0" />
      <mass
        value="0.592" />
      <inertia
        ixx="0.0017773"
        ixy="5.113E-10"
        ixz="-0.0009434"
        iyy="0.0024327"
        iyz="2.952E-10"
        izz="0.00068127" />
    </inertial>
    <visual>
      <origin
        xyz="0 0 0"
        rpy="0 0 0" />
      <geometry>
        <mesh
          filename="/home/jsh/문서/jsh/simulation/quad/meshes/HR_calf_link.STL" />
      </geometry>
      <material
        name="">
        <color
          rgba="0.75294 0.75294 0.75294 1" />
      </material>
    </visual>
    <collision>
      <origin
        xyz="0 0 0"
        rpy="0 0 0" />
      <geometry>
        <mesh
          filename="/home/jsh/문서/jsh/simulation/quad/meshes/HR_calf_link.STL" />
      </geometry>
    </collision>
  </link>
  <joint
    name="HR_calf_joint"
    type="revolute">
    <origin
      xyz="0.078665 0 -0.21613"
      rpy="0 0 0" />
    <parent
      link="HR_thigh_link" />
    <child
      link="HR_calf_link" />
    <axis
      xyz="0 1 0" />
    <limit
      lower="-0.524"
      upper="1.484"
      effort="42"
      velocity="19.7" />
  </joint>
  <link
    name="HR_foot_link">
    <inertial>
      <origin
        xyz="0.021095 -1.3544E-12 -0.057957"
        rpy="0 0 0" />
      <mass
        value="0.20444" />
      <inertia
        ixx="0.00024966"
        ixy="-1.0271E-10"
        ixz="7.9762E-05"
        iyy="0.00030517"
        iyz="-3.7368E-11"
        izz="5.9551E-05" />
    </inertial>
    <visual>
      <origin
        xyz="0 0 0"
        rpy="0 0 0" />
      <geometry>
        <mesh
          filename="/home/jsh/문서/jsh/simulation/quad/meshes/HR_foot_link.STL" />
      </geometry>
      <material
        name="">
        <color
          rgba="0.75294 0.75294 0.75294 1" />
      </material>
    </visual>
    <collision>
      <origin
        xyz="0 0 0"
        rpy="0 0 0" />
      <geometry>
        <mesh
          filename="/home/jsh/문서/jsh/simulation/quad/meshes/HR_foot_link.STL" />
      </geometry>
    </collision>
  </link>
  <joint
    name="HR_foot_joint"
    type="revolute">
    <origin
      xyz="-0.1225 0 -0.21218"
      rpy="0 0 0" />
    <parent
      link="HR_calf_link" />
    <child
      link="HR_foot_link" />
    <axis
      xyz="0 1 0" />
    <limit
      lower="-1.571"
      upper="0.524"
      effort="56"
      velocity="14.8" />
  </joint>
  <link
    name="HR_foot_contact_link">
    <inertial>
      <origin
        xyz="0.016812 2.2204E-16 -0.04619"
        rpy="0 0 0" />
      <mass
        value="0.033311" />
      <inertia
        ixx="7.0429E-06"
        ixy="-4.4375E-21"
        ixz="-2.5809E-07"
        iyy="1.0583E-05"
        iyz="-2.717E-21"
        izz="7.658E-06" />
    </inertial>
    <visual>
      <origin
        xyz="0 0 0"
        rpy="0 0 0" />
      <geometry>
        <mesh
          filename="/home/jsh/문서/jsh/simulation/quad/meshes/HR_foot_contact_link.STL" />
      </geometry>
      <material
        name="">
        <color
          rgba="1 1 1 1" />
      </material>
    </visual>
    <collision>
      <origin
        xyz="0 0 0"
        rpy="0 0 0" />
      <geometry>
        <mesh
          filename="/home/jsh/문서/jsh/simulation/quad/meshes/HR_foot_contact_link.STL" />
      </geometry>
    </collision>
  </link>
  <joint
    name="HR_foot_contact_joint"
    type="fixed">
    <origin
      xyz="0.0376222157658208 0 -0.103366188286448"
      rpy="0 0 0" />
    <parent
      link="HR_foot_link" />
    <child
      link="HR_foot_contact_link" />
    <axis
      xyz="0 0 0" />
  </joint>
  <link
    name="FL_hip_link">
    <inertial>
      <origin
        xyz="-0.044964 0.03664 4.8852E-05"
        rpy="0 0 0" />
      <mass
        value="1.385" />
      <inertia
        ixx="0.00055198"
        ixy="-2.2357E-06"
        ixz="2.7997E-09"
        iyy="0.00081827"
        iyz="1.4339E-09"
        izz="0.00046473" />
    </inertial>
    <visual>
      <origin
        xyz="0 0 0"
        rpy="0 0 0" />
      <geometry>
        <mesh
          filename="/home/jsh/문서/jsh/simulation/quad/meshes/FL_hip_link.STL" />
      </geometry>
      <material
        name="">
        <color
          rgba="0.75294 0.75294 0.75294 1" />
      </material>
    </visual>
    <collision>
      <origin
        xyz="0 0 0"
        rpy="0 0 0" />
      <geometry>
        <mesh
          filename="/home/jsh/문서/jsh/simulation/quad/meshes/FL_hip_link.STL" />
      </geometry>
    </collision>
  </link>
  <joint
    name="FL_hip_joint"
    type="revolute">
    <origin
      xyz="0.375 0.0225 0"
      rpy="0 0 0" />
    <parent
      link="base" />
    <child
      link="FL_hip_link" />
    <axis
      xyz="1 0 0" />
    <limit
      lower="-0.6109"
      upper="0.6109"
      effort="28"
      velocity="29.6" />
  </joint>
  <link
    name="FL_thigh_link">
    <inertial>
      <origin
        xyz="-0.023596 0.00079279 -0.091792"
        rpy="0 0 0" />
      <mass
        value="3.021" />
      <inertia
        ixx="0.004162"
        ixy="-9.7559E-08"
        ixz="-0.00074907"
        iyy="0.005605"
        iyz="-6.3565E-07"
        izz="0.0015471" />
    </inertial>
    <visual>
      <origin
        xyz="0 0 0"
        rpy="0 0 0" />
      <geometry>
        <mesh
          filename="/home/jsh/문서/jsh/simulation/quad/meshes/FL_thigh_link.STL" />
      </geometry>
      <material
        name="">
        <color
          rgba="0.75294 0.75294 0.75294 1" />
      </material>
    </visual>
    <collision>
      <origin
        xyz="0 0 0"
        rpy="0 0 0" />
      <geometry>
        <mesh
          filename="/home/jsh/문서/jsh/simulation/quad/meshes/FL_thigh_link.STL" />
      </geometry>
    </collision>
  </link>
  <joint
    name="FL_thigh_joint"
    type="revolute">
    <origin
      xyz="0 0.115 0"
      rpy="0 0 0" />
    <parent
      link="FL_hip_link" />
    <child
      link="FL_thigh_link" />
    <axis
      xyz="0 1 0" />
    <limit
      lower="-2.0071"
      upper="1.484"
      effort="28"
      velocity="29.6" />
  </joint>
  <link
    name="FL_calf_link">
    <inertial>
      <origin
        xyz="0.014126 0.00012405 -0.094544"
        rpy="0 0 0" />
      <mass
        value="0.592" />
      <inertia
        ixx="0.0022555"
        ixy="3.795E-10"
        ixz="0.00037043"
        iyy="0.0024327"
        iyz="-4.5228E-10"
        izz="0.00020308" />
    </inertial>
    <visual>
      <origin
        xyz="0 0 0"
        rpy="0 0 0" />
      <geometry>
        <mesh
          filename="/home/jsh/문서/jsh/simulation/quad/meshes/FL_calf_link.STL" />
      </geometry>
      <material
        name="">
        <color
          rgba="0.75294 0.75294 0.75294 1" />
      </material>
    </visual>
    <collision>
      <origin
        xyz="0 0 0"
        rpy="0 0 0" />
      <geometry>
        <mesh
          filename="/home/jsh/문서/jsh/simulation/quad/meshes/FL_calf_link.STL" />
      </geometry>
    </collision>
  </link>
  <joint
    name="FL_calf_joint"
    type="revolute">
    <origin
      xyz="-0.059528 0 -0.22216"
      rpy="0 0 0" />
    <parent
      link="FL_thigh_link" />
    <child
      link="FL_calf_link" />
    <axis
      xyz="0 1 0" />
    <limit
      lower="-1.9199"
      upper="0.087"
      effort="42"
      velocity="19.7" />
  </joint>
  <link
    name="FL_foot_link">
    <inertial>
      <origin
        xyz="0.010724 -1.3835E-12 -0.040023"
        rpy="0 0 0" />
      <mass
        value="0.15434" />
      <inertia
        ixx="0.00010739"
        ixy="-6.0165E-10"
        ixz="2.2421E-05"
        iyy="0.00013375"
        iyz="-1.612E-10"
        izz="2.9724E-05" />
    </inertial>
    <visual>
      <origin
        xyz="0 0 0"
        rpy="0 0 0" />
      <geometry>
        <mesh
          filename="/home/jsh/문서/jsh/simulation/quad/meshes/FL_foot_link.STL" />
      </geometry>
      <material
        name="">
        <color
          rgba="0.75294 0.75294 0.75294 1" />
      </material>
    </visual>
    <collision>
      <origin
        xyz="0 0 0"
        rpy="0 0 0" />
      <geometry>
        <mesh
          filename="/home/jsh/문서/jsh/simulation/quad/meshes/FL_foot_link.STL" />
      </geometry>
    </collision>
  </link>
  <joint
    name="FL_foot_joint"
    type="revolute">
    <origin
      xyz="0.042544 0 -0.24128"
      rpy="0 0 0" />
    <parent
      link="FL_calf_link" />
    <child
      link="FL_foot_link" />
    <axis
      xyz="0 1 0" />
    <limit
      lower="-1.309"
      upper="0.785"
      effort="56"
      velocity="14.8" />
  </joint>
  <link
    name="FL_foot_contact_link">
    <inertial>
      <origin
        xyz="0.012722 -2.7756E-17 -0.047479"
        rpy="0 0 0" />
      <mass
        value="0.033311" />
      <inertia
        ixx="7.0027E-06"
        ixy="2.9228E-21"
        ixz="-2.0076E-07"
        iyy="1.0583E-05"
        iyz="1.2776E-21"
        izz="7.6982E-06" />
    </inertial>
    <visual>
      <origin
        xyz="0 0 0"
        rpy="0 0 0" />
      <geometry>
        <mesh
          filename="/home/jsh/문서/jsh/simulation/quad/meshes/FL_foot_contact_link.STL" />
      </geometry>
      <material
        name="">
        <color
          rgba="1 1 1 1" />
      </material>
    </visual>
    <collision>
      <origin
        xyz="0 0 0"
        rpy="0 0 0" />
      <geometry>
        <mesh
          filename="/home/jsh/문서/jsh/simulation/quad/meshes/FL_foot_contact_link.STL" />
      </geometry>
    </collision>
  </link>
  <joint
    name="FL_foot_contact_joint"
    type="fixed">
    <origin
      xyz="0.0181173331571785 0 -0.0676148078402328"
      rpy="0 0 0" />
    <parent
      link="FL_foot_link" />
    <child
      link="FL_foot_contact_link" />
    <axis
      xyz="0 0 0" />
  </joint>
  <link
    name="FR_hip_link">
    <inertial>
      <origin
        xyz="-0.026196 -0.039035 -5.8825E-05"
        rpy="0 0 0" />
      <mass
        value="1.268" />
      <inertia
        ixx="0.0005559"
        ixy="1.3767E-05"
        ixz="-2.7997E-09"
        iyy="0.00078767"
        iyz="1.4339E-09"
        izz="0.00044966" />
    </inertial>
    <visual>
      <origin
        xyz="0 0 0"
        rpy="0 0 0" />
      <geometry>
        <mesh
          filename="/home/jsh/문서/jsh/simulation/quad/meshes/FR_hip_link.STL" />
      </geometry>
      <material
        name="">
        <color
          rgba="0.75294 0.75294 0.75294 1" />
      </material>
    </visual>
    <collision>
      <origin
        xyz="0 0 0"
        rpy="0 0 0" />
      <geometry>
        <mesh
          filename="/home/jsh/문서/jsh/simulation/quad/meshes/FR_hip_link.STL" />
      </geometry>
    </collision>
  </link>
  <joint
    name="FR_hip_joint"
    type="revolute">
    <origin
      xyz="0.375 -0.0225 0"
      rpy="0 0 0" />
    <parent
      link="base" />
    <child
      link="FR_hip_link" />
    <axis
      xyz="1 0 0" />
    <limit
      lower="-0.6109"
      upper="0.6109"
      effort="28"
      velocity="29.6" />
  </joint>
  <link
    name="FR_thigh_link">
    <inertial>
      <origin
        xyz="-0.025461 -0.00079281 -0.091292"
        rpy="0 0 0" />
      <mass
        value="3.021" />
      <inertia
        ixx="0.004157"
        ixy="2.3335E-07"
        ixz="-0.00075777"
        iyy="0.005605"
        iyz="5.9925E-07"
        izz="0.0015521" />
    </inertial>
    <visual>
      <origin
        xyz="0 0 0"
        rpy="0 0 0" />
      <geometry>
        <mesh
          filename="/home/jsh/문서/jsh/simulation/quad/meshes/FR_thigh_link.STL" />
      </geometry>
      <material
        name="">
        <color
          rgba="0.75294 0.75294 0.75294 1" />
      </material>
    </visual>
    <collision>
      <origin
        xyz="0 0 0"
        rpy="0 0 0" />
      <geometry>
        <mesh
          filename="/home/jsh/문서/jsh/simulation/quad/meshes/FR_thigh_link.STL" />
      </geometry>
    </collision>
  </link>
  <joint
    name="FR_thigh_joint"
    type="revolute">
    <origin
      xyz="0 -0.115 0"
      rpy="0 0 0" />
    <parent
      link="FR_hip_link" />
    <child
      link="FR_thigh_link" />
    <axis
      xyz="0 1 0" />
    <limit
      lower="-2.0071"
      upper="1.484"
      effort="28"
      velocity="29.6" />
  </joint>
  <link
    name="FR_calf_link">
    <inertial>
      <origin
        xyz="0.014126 -0.00012675 -0.094544"
        rpy="0 0 0" />
      <mass
        value="0.592" />
      <inertia
        ixx="0.0022555"
        ixy="-3.795E-10"
        ixz="0.00037043"
        iyy="0.0024327"
        iyz="4.5228E-10"
        izz="0.00020308" />
    </inertial>
    <visual>
      <origin
        xyz="0 0 0"
        rpy="0 0 0" />
      <geometry>
        <mesh
          filename="/home/jsh/문서/jsh/simulation/quad/meshes/FR_calf_link.STL" />
      </geometry>
      <material
        name="">
        <color
          rgba="0.75294 0.75294 0.75294 1" />
      </material>
    </visual>
    <collision>
      <origin
        xyz="0 0 0"
        rpy="0 0 0" />
      <geometry>
        <mesh
          filename="/home/jsh/문서/jsh/simulation/quad/meshes/FR_calf_link.STL" />
      </geometry>
    </collision>
  </link>
  <joint
    name="FR_calf_joint"
    type="revolute">
    <origin
      xyz="-0.059528 0 -0.22216"
      rpy="0 0 0" />
    <parent
      link="FR_thigh_link" />
    <child
      link="FR_calf_link" />
    <axis
      xyz="0 1 0" />
    <limit
      lower="-1.9199"
      upper="0.087"
      effort="42"
      velocity="19.7" />
  </joint>
  <link
    name="FR_foot_link">
    <inertial>
      <origin
        xyz="0.010724 -1.3833E-12 -0.040023"
        rpy="0 0 0" />
      <mass
        value="0.15434" />
      <inertia
        ixx="0.00010739"
        ixy="-6.0165E-10"
        ixz="2.2421E-05"
        iyy="0.00013375"
        iyz="-1.612E-10"
        izz="2.9724E-05" />
    </inertial>
    <visual>
      <origin
        xyz="0 0 0"
        rpy="0 0 0" />
      <geometry>
        <mesh
          filename="/home/jsh/문서/jsh/simulation/quad/meshes/FR_foot_link.STL" />
      </geometry>
      <material
        name="">
        <color
          rgba="0.75294 0.75294 0.75294 1" />
      </material>
    </visual>
    <collision>
      <origin
        xyz="0 0 0"
        rpy="0 0 0" />
      <geometry>
        <mesh
          filename="/home/jsh/문서/jsh/simulation/quad/meshes/FR_foot_link.STL" />
      </geometry>
    </collision>
  </link>
  <joint
    name="FR_foot_joint"
    type="revolute">
    <origin
      xyz="0.042544 0 -0.24128"
      rpy="0 0 0" />
    <parent
      link="FR_calf_link" />
    <child
      link="FR_foot_link" />
    <axis
      xyz="0 1 0" />
    <limit
      lower="-1.309"
      upper="0.785"
      effort="56"
      velocity="14.8" />
  </joint>
  <link
    name="FR_foot_contact_link">
    <inertial>
      <origin
        xyz="0.012722 2.498E-16 -0.047479"
        rpy="0 0 0" />
      <mass
        value="0.033311" />
      <inertia
        ixx="7.0027E-06"
        ixy="5.7207E-21"
        ixz="-2.0076E-07"
        iyy="1.0583E-05"
        iyz="2.1103E-21"
        izz="7.6982E-06" />
    </inertial>
    <visual>
      <origin
        xyz="0 0 0"
        rpy="0 0 0" />
      <geometry>
        <mesh
          filename="/home/jsh/문서/jsh/simulation/quad/meshes/FR_foot_contact_link.STL" />
      </geometry>
      <material
        name="">
        <color
          rgba="1 1 1 1" />
      </material>
    </visual>
    <collision>
      <origin
        xyz="0 0 0"
        rpy="0 0 0" />
      <geometry>
        <mesh
          filename="/home/jsh/문서/jsh/simulation/quad/meshes/FR_foot_contact_link.STL" />
      </geometry>
    </collision>
  </link>
  <joint
    name="FR_foot_contact_joint"
    type="fixed">
    <origin
      xyz="0.0181173331571765 0 -0.067614807840233"
      rpy="0 0 0" />
    <parent
      link="FR_foot_link" />
    <child
      link="FR_foot_contact_link" />
    <axis
      xyz="0 0 0" />
  </joint>
</robot>